<mujoco>

  <option timestep="0.001" gravity="0 0 -2" />

  <default class='0'>
    <geom mindist="0.0" compliance="0.0001" timeconst="0.0001"/>
  </default>

  <body>
		<geom name="estimator" type="sphere" pos="0 3 2" size=".1" rgba=".3 .3 .9 .4"
			contype="0" conaffinity="0"/>
		<geom type="plane" pos="0 3 -2" size="2 3 4" rgba=".4 .4 .4 1"/>
    	<geom type="plane" pos="0 -0.10 0" zaxis ="0 1 0" size="2 2 .4" rgba=".35 .4 .4 1"/>

		<body>
			<geom type="sphere" pos="0 6 0" size=".075" rgba=".1 .9 .1 1"/>
			<joint type="slide" pos="0 6 0" axis="1 0 0" ref="0"/>
			<joint type="slide" pos="0 6 0" axis="0 1 0" ref="6"/>
			<joint type="slide" pos="0 6 0" axis="0 0 1" ref="0"/>
		</body>

		<body>
			<geom type="box" pos="0 0 0" size=".1 0.05 .1" rgba=".9 .9 .1 1" mass="1"/>
			<joint name="paddle_h" type="slide" pos="0 0 0" axis="1 0 0" damping="10" islimited="true" range="-2 2" />
			<joint name="paddle_v" type="slide" pos="0 0 0" axis="0 0 1" damping="10" islimited="true" range="-2 2"/>
		</body>
	</body>

	<customfield>
		<custom name="noise" data="0.05 0.05 0.30"/>
		<custom name="getstate" data="1"/>
	</customfield>

  <keyframe>
    <key qpos='0 6 0 0 0' qvel='-1.50 -8 +1.50 0 0'/>
    <key qpos='0 6 0 0 0' qvel='-0.25 -6 +1.70 0 0'/>
    <key qpos='0 6 0 0 0' qvel='-0.50 -9 -1.50 0 0'/>
    <key qpos='0 6 0 0 0' qvel='+1.00 -8 +2.50 0 0'/>
    <key qpos='0 6 0 0 0' qvel='-0.50 -5 +1.50 0 0'/>
    <key qpos='0 6 0 0 0' qvel='-1.50 -5 -0.10 0 0'/>
    <key qpos='0 6 0 0 0' qvel='-1.00 -6 +2.00 0 0'/>
    <key qpos='0 6 0 0 0' qvel='+1.75 -6 +0.00 0 0'/>
    <key qpos='0 6 0 0 0' qvel='+0.00 -4 +2.75 0 0'/>
    <key qpos='0 6 0 0 0' qvel='+0.00 -5 +1.00 0 0'/>
  </keyframe>

  <actuator>
    <position joint="paddle_h" kp="250"/>
    <position joint="paddle_v" kp="250"/>
  </actuator>
  
</mujoco>
